<?xml version="1.0"?>

<robot xmlns:xacro="http://www.ros.org/wiki/xacro">

<xacro:macro name="wheel" params="prefix parent x y z roll">

    <link name="${prefix}_link">
        <visual>
            <geometry>
                <cylinder length="0.1" radius="0.1"/>
            </geometry>
            <origin xyz="0 0 0" rpy="0 0 0"/>
        </visual>
        <collision>
            <geometry>
                <cylinder length="0.1" radius="0.1"/>
            </geometry>
            <origin xyz="0 0 0" rpy="0 0 0"/>
        </collision>
        <inertial>
            <mass value="1.0"/>
            <origin xyz="0 0 0"/>
            <inertia ixx="0.083" ixy="0.0" ixz="0.0" iyy="0.021" iyz="0.0" izz="0.1"/>
        </inertial>
    </link>
    
    <joint name="${prefix}_joint" type="continuous">
        <parent link="${parent}"/>
        <child link="${prefix}_link"/>
        <origin xyz="${x} ${y} ${z}" rpy="${roll} 0 0"/>
        <axis xyz="0 0 1" />
    </joint>

</xacro:macro>


</robot>