<?xml version="1.0" ?>
<!-- =================================================================================== -->
<!-- |    This document was autogenerated by xacro from /home/emerito/catkin_ws/src/donatello_sim/urdf/donatello.urdf.xacro | -->
<!-- |    EDITING THIS FILE BY HAND IS NOT RECOMMENDED                                 | -->
<!-- =================================================================================== -->
<!-- TO-DO -->
<!-- change sizes -->
<!-- change inertia -->
<!-- MEDIDAS EN METROS -->
<robot name="donatello">
  <!-- SIZES -->
  <!-- INERTIA -->
  <!-- LINKS -->
  <link name="dummy_link">
    </link>

 <!-- Base Blanca -->
  <link name="base_link">
    <visual>
      <geometry>
        <box size="0.55 0.35 0.165"/> <!-- Geometría. x y z (altura). -->
      </geometry>
            <origin rpy="0 0 0" xyz="0.025 0 0.0"/>
      <material name = "yellow">
  	<color rgba="1 1 0 1"/>
      </material>
    </visual>
    <collision>
      <geometry>
        <box size="0.55 0.35 0.165 "/> <!-- Colisión. x y z (altura). -->
      </geometry>
    </collision>

    <inertial>
      <mass value="1.0"/>
      <origin xyz="0 0 0"/>
      <inertia ixx="0.083" ixy="0.0" ixz="0.0" iyy="0.021" iyz="0.0" izz="0.1"/>
    </inertial>
  </link>
  <!-- Inercia No revisado -->

 <!-- Link trasero -->
  <link name="rear_axle_link">

    <visual>
      <geometry>
        <cylinder length="0.03" radius="0.006"/>  <!-- Geometría del cilíndro -->
      </geometry>
      <origin rpy="0 -1.5707963 0" xyz="0.205 0 0.0825"/> <!-- Origen. rpy: lugar de uniones (roll pitch yaw, ejes xyz pero de giro). xyz: espacio. -->
      <material name = "yellow">
  	<color rgba="1 1 0 1"/>
      </material>
    </visual>

    <visual>    
      <geometry>
        <box size="0.03 0.49 0.03"/>   <!-- Perfil horizontal -->
      </geometry>
      <origin rpy="0 0 0" xyz="0.235 0 0.0825"/>
    </visual>

    <visual>
      <geometry>
        <box size="0.03 0.03 0.15"/> <!-- Perfil vertical izquierdo -->
      </geometry>
      <origin rpy="0 0 0" xyz="0.235 0.230 -0.0075"/>
    </visual>

    <visual>
      <geometry>
        <box size="0.03 0.03 0.15"/> <!-- Perfil vertical derecho -->
      </geometry>
      <origin rpy="0 0 0" xyz="0.235 -0.230 -0.0075"/>
    </visual>
    <!-- 24/10/24 -->

    <collision>
      <geometry>
        <cylinder length="0.03" radius="0.006"/>
      </geometry>
      <origin rpy="0 -1.5707963 0" xyz="-0.03 0 0"/>
    </collision>
    <collision>
      <geometry>
        <box size="0.05 0.6 0.05"/>
      </geometry>
      <origin rpy="0 0 0" xyz="-0.07500000000000001 0 0"/>
    </collision>
    <collision>
      <geometry>
        <box size="0.05 0.05 0.4"/>
      </geometry>
      <origin rpy="0 0 0" xyz="-0.07500000000000001 0.325 -0.17500000000000002"/>
    </collision>
    <collision>
      <geometry>
        <box size="0.05 0.05 0.4"/>
      </geometry>
      <origin rpy="0 0 0" xyz="-0.07500000000000001 -0.325 -0.17500000000000002"/>
    </collision>
    <inertial>
      <mass value="1.0"/>
      <origin xyz="0 0 0"/>
      <inertia ixx="0.083" ixy="0.0" ixz="0.0" iyy="0.021" iyz="0.0" izz="0.1"/>
    </inertial>
  </link>
  
 <!-- Triangulo Base Izquierdo -->
  <link name="front_left_axle_link">
    <visual>
      <geometry>
        <box size="0.03 0.03 0.26"/>
      </geometry>
      <origin rpy="0 0.78539815 0" xyz="-0.175 -0.1 0.025"/>
    </visual>
    <visual>
      <geometry>
        <box size="0.03 0.03 0.26"/>
      </geometry>
      <origin rpy="0 -0.78539815 0" xyz="0.025 -0.1 0.025"/>
    </visual>
    <collision>
      <geometry>
        <box size="0.03 0.03 0.26"/>
      </geometry>
      <origin rpy="0 0.78539815 0" xyz="-0.175 -0.195 -0.1"/>
    </collision>
    <collision>
      <geometry>
        <box size="0.03 0.03 0.26"/>
      </geometry>
      <origin rpy="0 -0.78539815 0" xyz="0.025 -0.195 -0.1"/>
    </collision>
    <inertial>
      <mass value="1.0"/>
      <origin xyz="0 0 0"/>
      <inertia ixx="0.083" ixy="0.0" ixz="0.0" iyy="0.021" iyz="0.0" izz="0.1"/>
    </inertial>
  </link>
  
   <!-- Triangulo Base Derecho-->
  <link name="front_right_axle_link">
    <visual>
      <geometry>
        <box size="0.03 0.03 0.26"/>
      </geometry>
      <origin rpy="0 0.78539815 0" xyz="-0.175 0.1 0.025"/>
    </visual>
    <visual>
      <geometry>
	<box size="0.03 0.03 0.26"/>
      </geometry>
      <origin rpy="0 -0.78539815 0" xyz="0.025 0.1 0.025"/>
    </visual>
    <collision>
      <geometry>
	<box size="0.03 0.03 0.26"/>
      </geometry>
      <origin rpy="0 0.78539815 0" xyz="-0.1 0.195 -0.1"/>
    </collision>
    <collision>
      <geometry>
	<box size="0.03 0.03 0.26"/>
      </geometry>
      <origin rpy="0 -0.78539815 0" xyz="0.1 0.195 -0.1"/>
    </collision>
    <inertial>
      <mass value="1.0"/>
      <origin xyz="0 0 0"/>
      <inertia ixx="0.083" ixy="0.0" ixz="0.0" iyy="0.021" iyz="0.0" izz="0.1"/>
    </inertial>
  </link>
  
  <!-- JOINTS -->
  <joint name="dummy_joint" type="fixed">
    <parent link="dummy_link"/>
    <child link="base_link"/>
    <origin rpy="0 0 0" xyz="0 0 0"/>
  </joint>
  <joint name="rear_axle_joint" type="continuous">
    <parent link="base_link"/>
    <child link="rear_axle_link"/>
    <origin rpy="0 0 0" xyz="-0.5 0 -0.15"/>
    <axis xyz="1 0 0"/>
  </joint>
  <joint name="front_left_axle_joint" type="continuous">
    <parent link="base_link"/>
    <child link="front_left_axle_link"/>
    <origin rpy="0 0 0" xyz="0.3 0.325 -0.15"/>
    <axis xyz="0 1 0"/>
  </joint>
  <joint name="front_right_axle_joint" type="continuous">
    <parent link="base_link"/>
    <child link="front_right_axle_link"/>
    <origin rpy="0 0 0" xyz="0.3 -0.325 -0.15"/>
    <axis xyz="0 1 0"/>
  </joint>
  <link name="back_left_wheel_link">
    <visual>
      <geometry>
        <cylinder length="0.07" radius="0.045"/>
      </geometry>
      <origin rpy="0 0 0" xyz="0 0 0"/>
    </visual>
    <collision>
      <geometry>
        <cylinder length="0.07" radius="0.045"/>
      </geometry>
      <origin rpy="0 0 0" xyz="0 0 0"/>
    </collision>
    <inertial>
      <mass value="1.0"/>
      <origin xyz="0 0 0"/>
      <inertia ixx="0.083" ixy="0.0" ixz="0.0" iyy="0.021" iyz="0.0" izz="0.1"/>
    </inertial>
  </link>
  <joint name="back_left_wheel_joint" type="continuous">
    <parent link="rear_axle_link"/>
    <child link="back_left_wheel_link"/>
    <origin rpy="1.5707963 0 0" xyz="-0.07500000000000001 0.39999999999999997 -0.4"/>
    <axis xyz="0 0 1"/>
  </joint>
  <link name="back_right_wheel_link">
    <visual>
      <geometry>
        <cylinder length="0.07" radius="0.045"/>
      </geometry>
      <origin rpy="0 0 0" xyz="0 0 0"/>
    </visual>
    <collision>
      <geometry>
        <cylinder length="0.07" radius="0.045"/>
      </geometry>
      <origin rpy="0 0 0" xyz="0 0 0"/>
    </collision>
    <inertial>
      <mass value="1.0"/>
      <origin xyz="0 0 0"/>
      <inertia ixx="0.083" ixy="0.0" ixz="0.0" iyy="0.021" iyz="0.0" izz="0.1"/>
    </inertial>
  </link>
  <joint name="back_right_wheel_joint" type="continuous">
    <parent link="rear_axle_link"/>
    <child link="back_right_wheel_link"/>
    <origin rpy="-1.5707963 0 0" xyz="-0.07500000000000001 -0.39999999999999997 -0.4"/>
    <axis xyz="0 0 1"/>
  </joint>
  <link name="center_left_wheel_link">
    <visual>
      <geometry>
        <cylinder length="0.07" radius="0.045"/>
      </geometry>
      <origin rpy="0 0 0" xyz="0 0 0"/>
    </visual>
    <collision>
      <geometry>
        <cylinder length="0.07" radius="0.045"/>
      </geometry>
      <origin rpy="0 0 0" xyz="0 0 0"/>
    </collision>
    <inertial>
      <mass value="1.0"/>
      <origin xyz="0 0 0"/>
      <inertia ixx="0.083" ixy="0.0" ixz="0.0" iyy="0.021" iyz="0.0" izz="0.1"/>
    </inertial>
  </link>
  <joint name="center_left_wheel_joint" type="continuous">
    <parent link="front_left_axle_link"/>
    <child link="center_left_wheel_link"/>
    <origin rpy="1.5707963 0 0" xyz="-0.4 0.07500000000000001 -0.4"/>
    <axis xyz="0 0 1"/>
  </joint>
  <link name="center_right_wheel_link">
    <visual>
      <geometry>
        <cylinder length="0.07" radius="0.045"/>
      </geometry>
      <origin rpy="0 0 0" xyz="0 0 0"/>
    </visual>
    <collision>
      <geometry>
        <cylinder length="0.07" radius="0.045"/>
      </geometry>
      <origin rpy="0 0 0" xyz="0 0 0"/>
    </collision>
    <inertial>
      <mass value="1.0"/>
      <origin xyz="0 0 0"/>
      <inertia ixx="0.083" ixy="0.0" ixz="0.0" iyy="0.021" iyz="0.0" izz="0.1"/>
    </inertial>
  </link>
  <joint name="center_right_wheel_joint" type="continuous">
    <parent link="front_right_axle_link"/>
    <child link="center_right_wheel_link"/>
    <origin rpy="-1.5707963 0 0" xyz="-0.4 -0.07500000000000001 -0.4"/>
    <axis xyz="0 0 1"/>
  </joint>
  <link name="front_left_wheel_link">
    <visual>
      <geometry>
        <cylinder length="0.07" radius="0.045"/>
      </geometry>
      <origin rpy="0 0 0" xyz="0 0 1.95"/>
    </visual>
    <collision>
      <geometry>
        <cylinder length="0.07" radius="0.045"/>
      </geometry>
      <origin rpy="0 0 0" xyz="0 0 0"/>
    </collision>
    <inertial>
      <mass value="1.0"/>
      <origin xyz="0 0 0"/>
      <inertia ixx="0.083" ixy="0.0" ixz="0.0" iyy="0.021" iyz="0.0" izz="0.1"/>
    </inertial>
  </link>
  <joint name="front_left_wheel_joint" type="continuous">
    <parent link="front_left_axle_link"/>
    <child link="front_left_wheel_link"/>
    <origin rpy="1.5707963 0 0" xyz="0 0 0"/>
    <axis xyz="0 0 1"/>
  </joint>
  <link name="front_right_wheel_link">
    <visual>
      <geometry>
        <cylinder length="0.07" radius="0.045"/>
      </geometry>
      <origin rpy="0 0 0" xyz="-0.4 -0.50 2.03"/>
    </visual>
    <collision>
      <geometry>
        <cylinder length="0.07" radius="0.045"/>
      </geometry>
      <origin rpy="0 0 0" xyz="0 0 0"/>
    </collision>
    <inertial>
      <mass value="1.0"/>
      <origin xyz="0 0 0"/>
      <inertia ixx="0.083" ixy="0.0" ixz="0.0" iyy="0.021" iyz="0.0" izz="0.1"/>
    </inertial>
  </link>
  <joint name="front_right_wheel_joint" type="continuous">
    <parent link="front_right_axle_link"/>
    <child link="front_right_wheel_link"/>
    <origin rpy="-1.5707963 0 0" xyz="0.4 -0.07500000000000001 -0.4"/>
    <axis xyz="0 0 1"/>
  </joint>
</robot>
<!-- 
EJECUTAR ESTA LINEA ANTES DE HACER catkin_make

rosrun xacro xacro ~/catkin_ws/src/donatello_sim/urdf/donatello.urdf.xacro > ~/catkin_ws/src/donatello_sim/urdf/donatello.urdf

check_urdf ~/catkin_ws/src/donatello_sim/urdf/donatello.urdf

-->

